<mujoco model="ur3">
  <compiler angle="radian" meshdir="assets"/>

  <option integrator="implicitfast"/>

  <default>
    <default class="ur3">
      <material specular="0.5" shininess="0.25"/>
      <joint axis="0 1 0" range="-3.14159 3.14159" armature="0.1"/>
      <general gaintype="fixed" biastype="affine" ctrlrange="-3.1415 3.1415" gainprm="2000" biasprm="0 -2000 -400" forcerange="-100 100"/>
      <default class="size3">
        <default class="size3_limited">
          <joint range="-1.5708 1.5708"/>
          <general ctrlrange="-1.5708 1.5708"/>
        </default>
      </default>
      <default class="size1">
        <general gainprm="500" biasprm="0 -500 -100" forcerange="-20 20"/>
      </default>
      <default class="visual">
        <geom type="mesh" contype="0" conaffinity="0" group="2"/>
      </default>
      <default class="collision">
        <geom type="capsule" group="3"/>
        <default class="eef_collision">
          <geom type="cylinder"/>
        </default>
      </default>
      <site size="0.001" rgba="0.5 0.5 0.5 0.3" group="4"/>
    </default>
  </default>

  <asset>
    <mesh name="ur3_base" file="ur3_base.obj"/>
    <mesh name="ur3_shoulder" file="ur3_shoulder.obj"/>
    <mesh name="ur3_upperarm" file="ur3_upperarm.obj"/>
    <mesh name="ur3_forearm" file="ur3_forearm.obj"/>
    <mesh name="ur3_wrist1" file="ur3_wrist1.obj"/>
    <mesh name="ur3_wrist2" file="ur3_wrist2.obj"/>
    <mesh name="ur3_wrist3" file="ur3_wrist3.obj"/>
  </asset>

  <worldbody>
    <body name="base" pos="0 0 0" childclass="ur3">
      <inertial mass="2.0" pos="0 0 0" diaginertia="0.005625 0.00305317 0.00305317"/>
      <geom type="mesh" mesh="ur3_base"/>
      <body name="shoulder_link" pos="0 0 0.1519">
        <inertial mass="2.0" pos="0 0 0" diaginertia="0.00809316 0.00809316 0.005625"/>
        <joint name="shoulder_pan_joint" axis="0 0 1" range="-3.14159 3.14159" damping="0.1" limited="true"/>
        <geom type="mesh" mesh="ur3_shoulder"/>
        <body name="upper_arm_link" pos="0 0.1198 0">
          <inertial mass="3.42" pos="0 0 0.121825" diaginertia="0.0217285 0.0217285 0.00961875"/>
          <joint name="shoulder_lift_joint" axis="0 1 0"/>
          <geom type="mesh" mesh="ur3_upperarm"/>
          <body name="forearm_link" pos="0 -0.0925 0.24365">
            <inertial mass="1.26" pos="0 0 0.106625" diaginertia="0.00654681 0.00654681 0.00354375"/>
            <joint name="elbow_joint" axis="0 1 0"/>
            <geom type="mesh" mesh="ur3_forearm"/>
            <body name="wrist_1_link" pos="0 0 0.21325">
              <joint name="wrist_1_joint" axis="0 1 0"/>
              <geom type="mesh" mesh="ur3_wrist1"/>
              <body name="wrist_2_link" pos="0 0.08505 0">
                <joint name="wrist_2_joint" axis="0 0 1"/>
                <geom type="mesh" mesh="ur3_wrist2"/>
                <body name="wrist_3_link" pos="0 0 0.08535">
                  <joint name="wrist_3_joint" axis="0 1 0"/>
                  <geom type="mesh" mesh="ur3_wrist3"/>
                </body>
              </body>
            </body>
          </body>
        </body>
      </body>
    </body>
  </worldbody>

  <actuator>
    <general class="size3" name="shoulder_pan" joint="shoulder_pan_joint"/>
    <general class="size3" name="shoulder_lift" joint="shoulder_lift_joint"/>
    <general class="size3_limited" name="elbow" joint="elbow_joint"/>
    <general class="size1" name="wrist_1" joint="wrist_1_joint"/>
    <general class="size1" name="wrist_2" joint="wrist_2_joint"/>
    <general class="size1" name="wrist_3" joint="wrist_3_joint"/>
  </actuator>
</mujoco>
