<mujoco model="ur3">
  <compiler angle="radian" meshdir="assets"/>

  <!-- Gravity = 0 below -->
  <option integrator="implicit" timestep="0.002" gravity = "0 0 -9.81"/>
  
  <default>
    <default class="ur3">
      <material specular="0.5" shininess="0.25"/>
      <joint axis="0 1 0" range="-3.14159 3.14159" armature="0.1" damping="0.02"/>
      <general gaintype="fixed" biastype="affine" ctrlrange="-3.1415 3.1415" gainprm="2000" biasprm="0 -2000 -400" forcerange="-500 500"/>
      <default class="size3">
        <default class="size3_limited">
          <joint range="-1.5708 1.5708"/>
          <general ctrlrange="-1.5708 1.5708"/>
        </default>
      </default>
      <default class="size1">
        <general gainprm="500" biasprm="0 -500 -100" forcerange="-20 20"/>
      </default>
      <default class="visual">
        <geom type="mesh" contype="0" conaffinity="0" group="2"/>
      </default>
      <default class="collision">
        <geom type="capsule" group="3" size="0.03"/>
        <default class="eef_collision">
          <geom type="cylinder" size="0.02"/>
        </default>
      </default>
      <site size="0.001" rgba="0.5 0.5 0.5 0.3" group="4"/>
    </default>
  </default>

  <asset>
    <mesh name="ur3_base" file="ur3_base.obj" />
    <mesh name="ur3_shoulder" file="ur3_shoulder.obj" />
    <mesh name="ur3_upperarm" file="ur3_upperarm.obj" />
    <mesh name="ur3_forearm" file="ur3_forearm.obj" />
    <mesh name="ur3_wrist1" file="ur3_wrist1.obj" />
    <mesh name="ur3_wrist2" file="ur3_wrist2.obj" />
    <mesh name="ur3_wrist3" file="ur3_wrist3.obj" />

    <mesh name="pen" file="assets/Pen.STL" scale="0.001 0.001 0.001"/>
    <mesh name="bottle" file="assets/Bottle.STL" scale="0.001 0.001 0.001"/>
    <mesh name="matches" file="assets/Matches.STL" scale="0.001 0.001 0.001"/>
    <mesh name="mug" file="assets/Mug.STL" scale="0.001 0.001 0.001"/>
    <mesh name="parfum" file="assets/Parfum.STL" scale="0.001 0.001 0.001"/>

  </asset>

  <worldbody>

    <body name="pen" pos="0.5 0 0.05">
      <geom type="mesh" mesh="pen" mass="0.5" rgba="0.2 0.8 0.2 1"/>
    </body>
    <body name="bottle" pos="0.75 0 0.05">
      <geom type="mesh" mesh="bottle" mass="0.5" rgba="0.2 0.8 0.2 1"/>
    </body>
    <body name="matches" pos="1 0 0.05">
      <geom type="mesh" mesh="matches" mass="0.5" rgba="0.2 0.8 0.2 1"/>
    </body>
    <body name="mug" pos="1.25 0 0.05">
      <geom type="mesh" mesh="mug" mass="0.5" rgba="0.2 0.8 0.2 1"/>
    </body>
    <body name="parfum" pos="1.5 0 0.05">
      <geom type="mesh" mesh="parfum" mass="0.5" rgba="0.2 0.8 0.2 1"/>
    </body>

    <!--
    <geom name="matches" type="box" pos="0.5 0 0.05" size="0.096 0.04 0.014" rgba="1 0 0 1"/>
    -->
    <body name="base" pos="0 0 0" childclass="ur3" gravity = "false">
      <inertial mass="5.0" pos="0 0 0.05" diaginertia="0.02 0.02 0.02"/>
      <geom type="mesh" mesh="ur3_base"/>
      <body name="shoulder_link" pos="0 0 0.152">
        <inertial mass="3.0" pos="0 0 0.05" diaginertia="0.02 0.02 0.015"/>
        <joint name="shoulder_pan_joint" axis="0 0 1" range="-2.5 2.5" damping="0.001"/>
        <geom type="mesh" mesh="ur3_shoulder"/>
        <body name="upper_arm_link" pos="0 0.1198 0">
          <inertial mass="3.42" pos="0 0 0.1" diaginertia="0.03 0.03 0.02"/>
          <joint name="shoulder_lift_joint" axis="0 1 0" range="-2.5 2.5"/>
          <geom type="mesh" mesh="ur3_upperarm"/>
          <body name="forearm_link" pos="0 -0.0925 0.24365">
            <inertial mass="1.5" pos="0 0 0.08" diaginertia="0.02 0.02 0.01"/>
            <joint name="elbow_joint" axis="0 1 0" range="-2.5 2.5"/>
            <geom type="mesh" mesh="ur3_forearm"/>
            <body name="wrist_1_link" pos="0 0 0.21325">
              <inertial mass="3.42" pos="0 0 0.1" diaginertia="0.03 0.03 0.02"/>
              <joint name="wrist_1_joint" axis="0 1 0" range="-2.5 2.5"/>
              <geom type="mesh" mesh="ur3_wrist1"/>
              <body name="wrist_2_link" pos="0 0.08505 0">
                <inertial mass="3.42" pos="0 0 0.1" diaginertia="0.03 0.03 0.02"/>
                <joint name="wrist_2_joint" axis="0 0 1" range="-2.5 2.5"/>
                <geom type="mesh" mesh="ur3_wrist2"/>
                <body name="wrist_3_link" pos="0 0 0.08535">
                  <inertial mass="3.42" pos="0 0 0.1" diaginertia="0.03 0.03 0.02"/>
                  <joint name="wrist_3_joint" axis="0 1 0" range="-2.5 2.5"/>
                  <geom type="mesh" mesh="ur3_wrist3"/>
                </body>
              </body>
            </body>
          </body>
        </body>
      </body>
    </body>
  </worldbody>

  <actuator>
    <general class="size1" name="shoulder_pan" joint="shoulder_pan_joint" gainprm="1000" biasprm="0 -1000 -200" forcerange="-100 100"/>
    <general class="size3" name="shoulder_lift" joint="shoulder_lift_joint" gainprm="1000" biasprm="0 -1000 -200" forcerange="-100 100"/>
    <general class="size3_limited" name="elbow" joint="elbow_joint"/>
    <general class="size1" name="wrist_1" joint="wrist_1_joint"/>
    <general class="size1" name="wrist_2" joint="wrist_2_joint"/>
    <general class="size1" name="wrist_3" joint="wrist_3_joint"/>
  </actuator>
</mujoco>